<?xml version="1.0"?>
<robot name="amr_robot">
  
  <!-- Base Link -->
  <link name="base_link">
    <inertial>
      <mass value="10.0"/>
      <origin xyz="0 0 0"/>
      <inertia ixx="0.1" ixy="0" ixz="0" iyy="0.1" iyz="0" izz="0.1"/>
    </inertial>
    <visual name="visual">
      <origin xyz="0 0 0.1" rpy="0 0 0"/>
      <geometry><box size="0.6 0.4 0.15"/></geometry>
      <material name="blue"><color rgba="0.2 0.4 0.8 1"/></material>
    </visual>
    <collision name="collision">
      <origin xyz="0 0 0.1" rpy="0 0 0"/>
      <geometry><box size="0.6 0.4 0.15"/></geometry>
    </collision>
  </link>

  <!-- Front Left Wheel -->
  <link name="front_left_wheel">
    <inertial>
      <mass value="1.0"/>
      <inertia ixx="0.001" ixy="0" ixz="0" iyy="0.001" iyz="0" izz="0.001"/>
    </inertial>
    <visual name="visual">
      <origin xyz="0 0 0" rpy="1.5707 0 0"/>
      <geometry><cylinder radius="0.08" length="0.04"/></geometry>
      <material name="black"><color rgba="0.1 0.1 0.1 1"/></material>
    </visual>
    <collision name="collision">
      <origin xyz="0 0 0" rpy="1.5707 0 0"/>
      <geometry><cylinder radius="0.08" length="0.04"/></geometry>
    </collision>
  </link>

  <!-- Front Right Wheel -->
  <link name="front_right_wheel">
    <inertial>
      <mass value="1.0"/>
      <inertia ixx="0.001" ixy="0" ixz="0" iyy="0.001" iyz="0" izz="0.001"/>
    </inertial>
    <visual name="visual">
      <origin xyz="0 0 0" rpy="1.5707 0 0"/>
      <geometry><cylinder radius="0.08" length="0.04"/></geometry>
      <material name="black"><color rgba="0.1 0.1 0.1 1"/></material>
    </visual>
    <collision name="collision">
      <origin xyz="0 0 0" rpy="1.5707 0 0"/>
      <geometry><cylinder radius="0.08" length="0.04"/></geometry>
    </collision>
  </link>

  <!-- Rear Left Wheel -->
  <link name="rear_left_wheel">
    <inertial>
      <mass value="1.0"/>
      <inertia ixx="0.001" ixy="0" ixz="0" iyy="0.001" iyz="0" izz="0.001"/>
    </inertial>
    <visual name="visual">
      <origin xyz="0 0 0" rpy="1.5707 0 0"/>
      <geometry><cylinder radius="0.08" length="0.04"/></geometry>
      <material name="black"><color rgba="0.1 0.1 0.1 1"/></material>
    </visual>
    <collision name="collision">
      <origin xyz="0 0 0" rpy="1.5707 0 0"/>
      <geometry><cylinder radius="0.08" length="0.04"/></geometry>
    </collision>
  </link>

  <!-- Rear Right Wheel -->
  <link name="rear_right_wheel">
    <inertial>
      <mass value="1.0"/>
      <inertia ixx="0.001" ixy="0" ixz="0" iyy="0.001" iyz="0" izz="0.001"/>
    </inertial>
    <visual name="visual">
      <origin xyz="0 0 0" rpy="1.5707 0 0"/>
      <geometry><cylinder radius="0.08" length="0.04"/></geometry>
      <material name="black"><color rgba="0.1 0.1 0.1 1"/></material>
    </visual>
    <collision name="collision">
      <origin xyz="0 0 0" rpy="1.5707 0 0"/>
      <geometry><cylinder radius="0.08" length="0.04"/></geometry>
    </collision>
  </link>

  <!-- Joints -->
  <joint name="front_left_wheel_joint" type="continuous">
    <parent link="base_link"/>
    <child link="front_left_wheel"/>
    <origin xyz="0.2 0.2 0.04" rpy="0 0 0"/>
    <axis xyz="0 1 0"/>
  </joint>

  <joint name="front_right_wheel_joint" type="continuous">
    <parent link="base_link"/>
    <child link="front_right_wheel"/>
    <origin xyz="0.2 -0.2 0.04" rpy="0 0 0"/>
    <axis xyz="0 1 0"/>
  </joint>

  <joint name="rear_left_wheel_joint" type="continuous">
    <parent link="base_link"/>
    <child link="rear_left_wheel"/>
    <origin xyz="-0.2 0.2 0.04" rpy="0 0 0"/>
    <axis xyz="0 1 0"/>
  </joint>

  <joint name="rear_right_wheel_joint" type="continuous">
    <parent link="base_link"/>
    <child link="rear_right_wheel"/>
    <origin xyz="-0.2 -0.2 0.04" rpy="0 0 0"/>
    <axis xyz="0 1 0"/>
  </joint>

</robot>
